Workbook

Sheet 说明
B2: 经济自由本金测算表
B3: 2026-10 · 参数为今天购买力；确定性测算为名义金额 · 与 HTML 计算器同一套默认参数
B5: 这不是“保证一辈子不破产”的承诺。它把支出、通胀、社保、医疗、护理、长寿、收益序列和黑天鹅放在一起；输出是概率意义上的“够”。
B7: 三个概念
B8: 成功 | C8: 死亡前可投资资产从未为负，且死亡时资产不低于遗产目标（按 CPI 指数化）。
B9: 置信度 | C9: 例如 90%，表示 4,000 条模拟人生里约 90% 不破产；不是 100%。
B10: 所需本金 | C10: 在给定置信度下，今天至少需要的可投资净资产（不含自住房）。
B12: 怎么用
B13: 1 | C13: 只改“参数”表黄色单元格；“确定性测算”会自动更新。
B14: 2 | C14: “结果”表的蒙特卡洛区间来自 HTML 模型；改参数后请在 HTML 里重算，Excel 不会自动重跑 4,000 条路径。
B15: 3 | C15: “确定性测算”是简化版：不含医疗大额冲击、长期护理、收益率波动；用来理解现金流，不替代蒙特卡洛。
B18: 模型边界
B19: 未单独建模：个人养老金账户税优、海外资产汇率、房产税全国推开、遗产税、离婚/丧偶状态机、子女啃老、诈骗/诉讼、保险拒赔、医保目录变化、地方养老金差异。它们会改变结果，方向不一定。
B20: 所有“预期收益”都是假设，不是事实。请用区间思维，而不是单点数字。

Sheet 参数
B2: 参数（只改黄色单元格）
B3: 所有金额为今天（2026）购买力；百分比单元格已设为百分比格式。
B5: 参数 | C5: 值 | D5: 单位 | E5: 说明 / 来源
B6: 当前年龄 | C6: 40 | D6: 周岁 | E6: 你自己
B7: 配偶年龄 | C7: 38 | D7: 周岁 | E7: 1 人家庭忽略
B8: 停止工作年龄 | C8: 40 | D8: 周岁 | E8: 现在不工作 = 当前年龄
B9: 规划到年龄 | C9: 100 | D9: 周岁 | E9: 保守 100；压力测试 105
B10: 当前可投资净资产 | C10: 3000000 | D10: 元 | E10: 不含自住房
B12: 核心生活（元/月）
B13: 餐饮食品 | C13: 5000 | D13: 元/月 | E13: 不含医疗、保险、房贷
B14: 居住/物业/水电 | C14: 3000 | D14: 元/月 | E14: 不含医疗、保险、房贷
B15: 交通通讯 | C15: 1800 | D15: 元/月 | E15: 不含医疗、保险、房贷
B16: 衣着日用 | C16: 800 | D16: 元/月 | E16: 不含医疗、保险、房贷
B17: 娱乐旅游 | C17: 1200 | D17: 元/月 | E17: 不含医疗、保险、房贷
B18: 人情社交 | C18: 1000 | D18: 元/月 | E18: 不含医疗、保险、房贷
B19: 其他/不可预见 | C19: 1200 | D19: 元/月 | E19: 不含医疗、保险、房贷
B20: 核心月支出合计 | C20: =SUM(C13:C19) -> 14000 | D20: 元/月 | E20: 公式自动合计（7 项）
B21: 日常医疗 / 体检 | C21: 1000 | D21: 元/月 | E21: 随医疗通胀膨胀
B22: 商业保险年保费 | C22: 12000 | D22: 元/年 | E22: 全家合计；随年龄上升
B23: 退休后基础支出比例 | C23: 0.9 | D23: % | E23: 相对当前核心生活
B24: 房贷余额 | C24: 1000000 | D24: 元 | E24: 自住房不计入可投资资产
B25: 房贷利率 | C25: 0.032 | D25: % | E25: 名义固定利率
B26: 房贷剩余年限 | C26: 15 | D26: 年 | E26: 等额本息
B27: 房贷年供 | C27: =PMT(C25,C26,-C24) -> 84983.017 | D27: 元/年 | E27: 公式自动计算
B28: 子女当前年龄 | C28: 6 | D28: 周岁 | E28: 0 个子女填 0 并把年成本设 0
B29: 子女年成本 | C29: 20000 | D29: 元/年 | E29: 增量成本；不含家庭共同住房
B30: 子女支持到年龄 | C30: 22 | D30: 周岁 | E30: 默认本科毕业
B31: 社保月养老金（合计） | C31: 9618 | D31: 元/月 | E31: 今天币值；可由 HTML 公式估算
B32: 养老金开始年龄 | C32: 63 | D32: 周岁 | E32: 渐进式延迟退休后约为 63
B33: 养老金调整率 | C33: 0.02 | D33: % | E33: 名义；本表简化未用
B34: CPI 中枢 | C34: 0.02 | D34: %/年 | E34: 长期假设；2024/2025 实际为 0.2%/0.0%
B35: 医疗通胀 | C35: 0.05 | D35: %/年 | E35: CPI + 3% 的假设
B36: 教育通胀 | C36: 0.05 | D36: %/年 | E36: CPI + 3% 的假设
B37: 组合费后几何收益 | C37: 0.0384023 | D37: %/年 | E37: HTML 默认组合：30/30/30/10，费后
B38: 保费实际增长 | C38: 0.03 | D38: %/年 | E38: 随年龄上升
B39: 目标本金（测算用） | C39: 18619052 | D39: 元 | E39: 来自蒙特卡洛 90% 目标；可改
... B42: 自住房价值 | C42: 3000000 | D42: 元 | E42: 不计入可投资资产
B44: 大件 / 一次性支出
B45: 项目 | C45: 金额（元） | D45: 开始年龄 | E45: 每隔（年） | F45: 结束年龄
B46: 换车 | C46: 180000 | D46: 48 | E46: 8 | F46: 80
...

Sheet 确定性测算
A1: 确定性测算（简化版）
A2: 名义金额；假设双方都活到 100 岁，不建模死亡、卖房、遗产；不含收益波动、医疗大额冲击、长期护理。用于理解现金流，不替代蒙特卡洛。
A4: 0 | B4: 40 | C4: =1 -> 1 | D4: =参数!$C$20*12*C4*IF(B4>=参数!$C$8,参数!$C$23,1) -> 151200 | E4: =参数!$C$21*12*(1+参数!$C$35)^A4 -> 12000 | F4: =参数!$C$22*(1+参数!$C$34)^A4*(1+参数!$C$38)^A4 -> 12000 | G4: =IF(A4<参数!$C$26,参数!$C$27,0) -> 84983.017 | H4: =IF(参数!$C$28+A4<=参数!$C$30,参数!$C$29*(1+参数!$C$36)^A4,0) -> 20000 | I4: =IF(AND(B4>=参数!$D$46,B4<=参数!$F$46,MOD(B4-参数!$D$46,参数!$E$46)=0),参数!$C$46*C4,0)+IF(AND(B4>=参数!$D$47,B4<=参数!$F$47,MOD(B4-参数!$D$47,参数!$E$47)=0),参数!$C$47*C4,0)+IF(AND(B4>=参数!$D$48,B4<=参数!$F$48,MOD(B4-参数!$D$48,参数!$E$48)=0),参数!$C$48*C4,0) -> 0 | J4: =SUM(D4:I4) -> 280183.02 | K4: =IF(B4>=参数!$C$32,参数!$C$31*12*C4,0) -> 0 | L4: =J4-K4 -> 280183.02 | M4: =参数!$C$39 -> 18619052 | N4: =(M4-L4)*(1+参数!$C$37) -> 19043124
A5: 1 | B5: 41 | C5: =C4*(1+参数!$C$34) -> 1.02 | D5: =参数!$C$20*12*C5*IF(B5>=参数!$C$8,参数!$C$23,1) -> 154224 | E5: =参数!$C$21*12*(1+参数!$C$35)^A5 -> 12600 | F5: =参数!$C$22*(1+参数!$C$34)^A5*(1+参数!$C$38)^A5 -> 12607.2 | G5: =IF(A5<参数!$C$26,参数!$C$27,0) -> 84983.017 | H5: =IF(参数!$C$28+A5<=参数!$C$30,参数!$C$29*(1+参数!$C$36)^A5,0) -> 21000 | I5: =IF(AND(B5>=参数!$D$46,B5<=参数!$F$46,MOD(B5-参数!$D$46,参数!$E$46)=0),参数!$C$46*C5,0)+IF(AND(B5>=参数!$D$47,B5<=参数!$F$47,MOD(B5-参数!$D$47,参数!$E$47)=0),参数!$C$47*C5,0)+IF(AND(B5>=参数!$D$48,B5<=参数!$F$48,MOD(B5-参数!$D$48,参数!$E$48)=0),参数!$C$48*C5,0) -> 0 | J5: =SUM(D5:I5) -> 285414.22 | K5: =IF(B5>=参数!$C$32,参数!$C$31*12*C5,0) -> 0 | L5: =J5-K5 -> 285414.22 | M5: =N4 -> 19043124 | N5: =(M5-L5)*(1+参数!$C$37) -> 19478049
A6: 2 | B6: 42 | C6: =C5*(1+参数!$C$34) -> 1.0404 | D6: =参数!$C$20*12*C6*IF(B6>=参数!$C$8,参数!$C$23,1) -> 157308.48 | E6: =参数!$C$21*12*(1+参数!$C$35)^A6 -> 13230 | F6: =参数!$C$22*(1+参数!$C$34)^A6*(1+参数!$C$38)^A6 -> 13245.124 | G6: =IF(A6<参数!$C$26,参数!$C$27,0) -> 84983.017 | H6: =IF(参数!$C$28+A6<=参数!$C$30,参数!$C$29*(1+参数!$C$36)^A6,0) -> 22050 | I6: =IF(AND(B6>=参数!$D$46,B6<=参数!$F$46,MOD(B6-参数!$D$46,参数!$E$46)=0),参数!$C$46*C6,0)+IF(AND(B6>=参数!$D$47,B6<=参数!$F$47,MOD(B6-参数!$D$47,参数!$E$47)=0),参数!$C$47*C6,0)+IF(AND(B6>=参数!$D$48,B6<=参数!$F$48,MOD(B6-参数!$D$48,参数!$E$48)=0),参数!$C$48*C6,0) -> 0 | J6: =SUM(D6:I6) -> 290816.62 | K6: =IF(B6>=参数!$C$32,参数!$C$31*12*C6,0) -> 0 | L6: =J6-K6 -> 290816.62 | M6: =N5 -> 19478049 | N6: =(M6-L6)*(1+参数!$C$37) -> 19924066
A7: 3 | B7: 43 | C7: =C6*(1+参数!$C$34) -> 1.061208 | D7: =参数!$C$20*12*C7*IF(B7>=参数!$C$8,参数!$C$23,1) -> 160454.65 | E7: =参数!$C$21*12*(1+参数!$C$35)^A7 -> 13891.5 | F7: =参数!$C$22*(1+参数!$C$34)^A7*(1+参数!$C$38)^A7 -> 13915.328 | G7: =IF(A7<参数!$C$26,参数!$C$27,0) -> 84983.017 | H7: =IF(参数!$C$28+A7<=参数!$C$30,参数!$C$29*(1+参数!$C$36)^A7,0) -> 23152.5 | I7: =IF(AND(B7>=参数!$D$46,B7<=参数!$F$46,MOD(B7-参数!$D$46,参数!$E$46)=0),参数!$C$46*C7,0)+IF(AND(B7>=参数!$D$47,B7<=参数!$F$47,MOD(B7-参数!$D$47,参数!$E$47)=0),参数!$C$47*C7,0)+IF(AND(B7>=参数!$D$48,B7<=参数!$F$48,MOD(B7-参数!$D$48,参数!$E$48)=0),参数!$C$48*C7,0) -> 0 | J7: =SUM(D7:I7) -> 296396.99 | K7: =IF(B7>=参数!$C$32,参数!$C$31*12*C7,0) -> 0 | L7: =J7-K7 -> 296396.99 | M7: =N6 -> 19924066 | N7: =(M7-L7)*(1+参数!$C$37) -> 20381417
A8: 4 | B8: 44 | C8: =C7*(1+参数!$C$34) -> 1.0824322 | D8: =参数!$C$20*12*C8*IF(B8>=参数!$C$8,参数!$C$23,1) -> 163663.74 | E8: =参数!$C$21*12*(1+参数!$C$35)^A8 -> 14586.075 | F8: =参数!$C$22*(1+参数!$C$34)^A8*(1+参数!$C$38)^A8 -> 14619.443 | G8: =IF(A8<参数!$C$26,参数!$C$27,0) -> 84983.017 | H8: =IF(参数!$C$28+A8<=参数!$C$30,参数!$C$29*(1+参数!$C$36)^A8,0) -> 24310.125 | I8: =IF(AND(B8>=参数!$D$46,B8<=参数!$F$46,MOD(B8-参数!$D$46,参数!$E$46)=0),参数!$C$46*C8,0)+IF(AND(B8>=参数!$D$47,B8<=参数!$F$47,MOD(B8-参数!$D$47,参数!$E$47)=0),参数!$C$47*C8,0)+IF(AND(B8>=参数!$D$48,B8<=参数!$F$48,MOD(B8-参数!$D$48,参数!$E$48)=0),参数!$C$48*C8,0) -> 0 | J8: =SUM(D8:I8) -> 302162.4 | K8: =IF(B8>=参数!$C$32,参数!$C$31*12*C8,0) -> 0 | L8: =J8-K8 -> 302162.4 | M8: =N7 -> 20381417 | N8: =(M8-L8)*(1+参数!$C$37) -> 20850344
A9: 5 | B9: 45 | C9: =C8*(1+参数!$C$34) -> 1.1040808 | D9: =参数!$C$20*12*C9*IF(B9>=参数!$C$8,参数!$C$23,1) -> 166937.02 | E9: =参数!$C$21*12*(1+参数!$C$35)^A9 -> 15315.379 | F9: =参数!$C$22*(1+参数!$C$34)^A9*(1+参数!$C$38)^A9 -> 15359.187 | G9: =IF(A9<参数!$C$26,参数!$C$27,0) -> 84983.017 | H9: =IF(参数!$C$28+A9<=参数!$C$30,参数!$C$29*(1+参数!$C$36)^A9,0) -> 25525.631 | I9: =IF(AND(B9>=参数!$D$46,B9<=参数!$F$46,MOD(B9-参数!$D$46,参数!$E$46)=0),参数!$C$46*C9,0)+IF(AND(B9>=参数!$D$47,B9<=参数!$F$47,MOD(B9-参数!$D$47,参数!$E$47)=0),参数!$C$47*C9,0)+IF(AND(B9>=参数!$D$48,B9<=参数!$F$48,MOD(B9-参数!$D$48,参数!$E$48)=0),参数!$C$48*C9,0) -> 66244.848 | J9: =SUM(D9:I9) -> 374365.08 | K9: =IF(B9>=参数!$C$32,参数!$C$31*12*C9,0) -> 0 | L9: =J9-K9 -> 374365.08 | M9: =N8 -> 20850344 | N9: =(M9-L9)*(1+参数!$C$37) -> 21262303
A10: 6 | B10: 46 | C10: =C9*(1+参数!$C$34) -> 1.1261624 | D10: =参数!$C$20*12*C10*IF(B10>=参数!$C$8,参数!$C$23,1) -> 170275.76 | E10: =参数!$C$21*12*(1+参数!$C$35)^A10 -> 16081.148 | F10: =参数!$C$22*(1+参数!$C$34)^A10*(1+参数!$C$38)^A10 -> 16136.362 | G10: =IF(A10<参数!$C$26,参数!$C$27,0) -> 84983.017 | H10: =IF(参数!$C$28+A10<=参数!$C$30,参数!$C$29*(1+参数!$C$36)^A10,0) -> 26801.913 | I10: =IF(AND(B10>=参数!$D$46,B10<=参数!$F$46,MOD(B10-参数!$D$46,参数!$E$46)=0),参数!$C$46*C10,0)+IF(AND(B10>=参数!$D$47,B10<=参数!$F$47,MOD(B10-参数!$D$47,参数!$E$47)=0),参数!$C$47*C10,0)+IF(AND(B10>=参数!$D$48,B10<=参数!$F$48,MOD(B10-参数!$D$48,参数!$E$48)=0),参数!$C$48*C10,0) -> 0 | J10: =SUM(D10:I10) -> 314278.2 | K10: =IF(B10>=参数!$C$32,参数!$C$31*12*C10,0) -> 0 | L10: =J10-K10 -> 314278.2 | M10: =N9 -> 21262303 | N10: =(M10-L10)*(1+参数!$C$37) -> 21752477
A11: 7 | B11: 47 | C11: =C10*(1+参数!$C$34) -> 1.1486857 | D11: =参数!$C$20*12*C11*IF(B11>=参数!$C$8,参数!$C$23,1) -> 173681.27 | E11: =参数!$C$21*12*(1+参数!$C$35)^A11 -> 16885.205 | F11: =参数!$C$22*(1+参数!$C$34)^A11*(1+参数!$C$38)^A11 -> 16952.862 | G11: =IF(A11<参数!$C$26,参数!$C$27,0) -> 84983.017 | H11: =IF(参数!$C$28+A11<=参数!$C$30,参数!$C$29*(1+参数!$C$36)^A11,0) -> 28142.008 | I11: =IF(AND(B11>=参数!$D$46,B11<=参数!$F$46,MOD(B11-参数!$D$46,参数!$E$46)=0),参数!$C$46*C11,0)+IF(AND(B11>=参数!$D$47,B11<=参数!$F$47,MOD(B11-参数!$D$47,参数!$E$47)=0),参数!$C$47*C11,0)+IF(AND(B11>=参数!$D$48,B11<=参数!$F$48,MOD(B11-参数!$D$48,参数!$E$48)=0),参数!$C$48*C11,0) -> 0 | J11: =SUM(D11:I11) -> 320644.37 | K11: =IF(B11>=参数!$C$32,参数!$C$31*12*C11,0) -> 0 | L11: =J11-K11 -> 320644.37 | M11: =N10 -> 21752477 | N11: =(M11-L11)*(1+参数!$C$37) -> 22254865
A12: 8 | B12: 48 | C12: =C11*(1+参数!$C$34) -> 1.1716594 | D12: =参数!$C$20*12*C12*IF(B12>=参数!$C$8,参数!$C$23,1) -> 177154.9 | E12: =参数!$C$21*12*(1+参数!$C$35)^A12 -> 17729.465 | F12: =参数!$C$22*(1+参数!$C$34)^A12*(1+参数!$C$38)^A12 -> 17810.677 | G12: =IF(A12<参数!$C$26,参数!$C$27,0) -> 84983.017 | H12: =IF(参数!$C$28+A12<=参数!$C$30,参数!$C$29*(1+参数!$C$36)^A12,0) -> 29549.109 | I12: =IF(AND(B12>=参数!$D$46,B12<=参数!$F$46,MOD(B12-参数!$D$46,参数!$E$46)=0),参数!$C$46*C12,0)+IF(AND(B12>=参数!$D$47,B12<=参数!$F$47,MOD(B12-参数!$D$47,参数!$E$47)=0),参数!$C$47*C12,0)+IF(AND(B12>=参数!$D$48,B12<=参数!$F$48,MOD(B12-参数!$D$48,参数!$E$48)=0),参数!$C$48*C12,0) -> 210898.69 | J12: =SUM(D12:I12) -> 538125.86 | K12: =IF(B12>=参数!$C$32,参数!$C$31*12*C12,0) -> 0 | L12: =J12-K12 -> 538125.86 | M12: =N11 -> 22254865 | N12: =(M12-L12)*(1+参数!$C$37) -> 22550712
A13: 9 | B13: 49 | C13: =C12*(1+参数!$C$34) -> 1.1950926 | D13: =参数!$C$20*12*C13*IF(B13>=参数!$C$8,参数!$C$23,1) -> 180698 | E13: =参数!$C$21*12*(1+参数!$C$35)^A13 -> 18615.939 | F13: =参数!$C$22*(1+参数!$C$34)^A13*(1+参数!$C$38)^A13 -> 18711.897 | G13: =IF(A13<参数!$C$26,参数!$C$27,0) -> 84983.017 | H13: =IF(参数!$C$28+A13<=参数!$C$30,参数!$C$29*(1+参数!$C$36)^A13,0) -> 31026.564 | I13: =IF(AND(B13>=参数!$D$46,B13<=参数!$F$46,MOD(B13-参数!$D$46,参数!$E$46)=0),参数!$C$46*C13,0)+IF(AND(B13>=参数!$D$47,B13<=参数!$F$47,MOD(B13-参数!$D$47,参数!$E$47)=0),参数!$C$47*C13,0)+IF(AND(B13>=参数!$D$48,B13<=参数!$F$48,MOD(B13-参数!$D$48,参数!$E$48)=0),参数!$C$48*C13,0) -> 0 | J13: =SUM(D13:I13) -> 334035.41 | K13: =IF(B13>=参数!$C$32,参数!$C$31*12*C13,0) -> 0 | L13: =J13-K13 -> 334035.41 | M13: =N12 -> 22550712 | N13: =(M13-L13)*(1+参数!$C$37) -> 23069848
A14: 10 | B14: 50 | C14: =C13*(1+参数!$C$34) -> 1.2189944 | D14: =参数!$C$20*12*C14*IF(B14>=参数!$C$8,参数!$C$23,1) -> 184311.96 | E14: =参数!$C$21*12*(1+参数!$C$35)^A14 -> 19546.736 | F14: =参数!$C$22*(1+参数!$C$34)^A14*(1+参数!$C$38)^A14 -> 19658.719 | G14: =IF(A14<参数!$C$26,参数!$C$27,0) -> 84983.017 | H14: =IF(参数!$C$28+A14<=参数!$C$30,参数!$C$29*(1+参数!$C$36)^A14,0) -> 32577.893 | I14: =IF(AND(B14>=参数!$D$46,B14<=参数!$F$46,MOD(B14-参数!$D$46,参数!$E$46)=0),参数!$C$46*C14,0)+IF(AND(B14>=参数!$D$47,B14<=参数!$F$47,MOD(B14-参数!$D$47,参数!$E$47)=0),参数!$C$47*C14,0)+IF(AND(B14>=参数!$D$48,B14<=参数!$F$48,MOD(B14-参数!$D$48,参数!$E$48)=0),参数!$C$48*C14,0) -> 316938.55 | J14: =SUM(D14:I14) -> 658016.87 | K14: =IF(B14>=参数!$C$32,参数!$C$31*12*C14,0) -> 0 | L14: =J14-K14 -> 658016.87 | M14: =N13 -> 23069848 | N14: =(M14-L14)*(1+参数!$C$37) -> 23272497
A15: 11 | B15: 51 | C15: =C14*(1+参数!$C$34) -> 1.2433743 | D15: =参数!$C$20*12*C15*IF(B15>=参数!$C$8,参数!$C$23,1) -> 187998.2 | E15: =参数!$C$21*12*(1+参数!$C$35)^A15 -> 20524.072 | F15: =参数!$C$22*(1+参数!$C$34)^A15*(1+参数!$C$38)^A15 -> 20653.45 | G15: =IF(A15<参数!$C$26,参数!$C$27,0) -> 84983.017 | H15: =IF(参数!$C$28+A15<=参数!$C$30,参数!$C$29*(1+参数!$C$36)^A15,0) -> 34206.787 | I15: =IF(AND(B15>=参数!$D$46,B15<=参数!$F$46,MOD(B15-参数!$D$46,参数!$E$46)=0),参数!$C$46*C15,0)+IF(AND(B15>=参数!$D$47,B15<=参数!$F$47,MOD(B15-参数!$D$47,参数!$E$47)=0),参数!$C$47*C15,0)+IF(AND(B15>=参数!$D$48,B15<=参数!$F$48,MOD(B15-参数!$D$48,参数!$E$48)=0),参数!$C$48*C15,0) -> 0 | J15: =SUM(D15:I15) -> 348365.52 | K15: =IF(B15>=参数!$C$32,参数!$C$31*12*C15,0) -> 0 | L15: =J15-K15 -> 348365.52 | M15: =N14 -> 23272497 | N15: =(M15-L15)*(1+参数!$C$37) -> 23804470
A16: 12 | B16: 52 | C16: =C15*(1+参数!$C$34) -> 1.2682418 | D16: =参数!$C$20*12*C16*IF(B16>=参数!$C$8,参数!$C$23,1) -> 191758.16 | E16: =参数!$C$21*12*(1+参数!$C$35)^A16 -> 21550.276 | F16: =参数!$C$22*(1+参数!$C$34)^A16*(1+参数!$C$38)^A16 -> 21698.515 | G16: =IF(A16<参数!$C$26,参数!$C$27,0) -> 84983.017 | H16: =IF(参数!$C$28+A16<=参数!$C$30,参数!$C$29*(1+参数!$C$36)^A16,0) -> 35917.127 | I16: =IF(AND(B16>=参数!$D$46,B16<=参数!$F$46,MOD(B16-参数!$D$46,参数!$E$46)=0),参数!$C$46*C16,0)+IF(AND(B16>=参数!$D$47,B16<=参数!$F$47,MOD(B16-参数!$D$47,参数!$E$47)=0),参数!$C$47*C16,0)+IF(AND(B16>=参数!$D$48,B16<=参数!$F$48,MOD(B16-参数!$D$48,参数!$E$48)=0),参数!$C$48*C16,0) -> 0 | J16: =SUM(D16:I16) -> 355907.09 | K16: =IF(B16>=参数!$C$32,参数!$C$31*12*C16,0) -> 0 | L16: =J16-K16 -> 355907.09 | M16: =N15 -> 23804470 | N16: =(M16-L16)*(1+参数!$C$37) -> 24349042
... A64: 60 | B64: 100 | C64: =C63*(1+参数!$C$34) -> 3.2810308 | D64: =参数!$C$20*12*C64*IF(B64>=参数!$C$8,参数!$C$23,1) -> 496091.86 | E64: =参数!$C$21*12*(1+参数!$C$35)^A64 -> 224150.23 | F64: =参数!$C$22*(1+参数!$C$34)^A64*(1+参数!$C$38)^A64 -> 231966.37 | G64: =IF(A64<参数!$C$26,参数!$C$27,0) -> 0 | H64: =IF(参数!$C$28+A64<=参数!$C$30,参数!$C$29*(1+参数!$C$36)^A64,0) -> 0 | I64: =IF(AND(B64>=参数!$D$46,B64<=参数!$F$46,MOD(B64-参数!$D$46,参数!$E$46)=0),参数!$C$46*C64,0)+IF(AND(B64>=参数!$D$47,B64<=参数!$F$47,MOD(B64-参数!$D$47,参数!$E$47)=0),参数!$C$47*C64,0)+IF(AND(B64>=参数!$D$48,B64<=参数!$F$48,MOD(B64-参数!$D$48,参数!$E$48)=0),参数!$C$48*C64,0) -> 0 | J64: =SUM(D64:I64) -> 952208.46 | K64: =IF(B64>=参数!$C$32,参数!$C$31*12*C64,0) -> 378678.19 | L64: =J64-K64 -> 573530.27 | M64: =N63 -> 99346986 | N64: =(M64-L64)*(1+参数!$C$37) -> 1.0256658e+08
B66: 期末资产 | C66: =N64 -> 1.0256658e+08
B67: 资产首次为负 | C67: =IFERROR(INDEX(B4:B64,MATCH(TRUE,INDEX(N4:N64<0,0),0)),"未耗尽") -> 未耗尽
B68: 最低期末资产 | C68: =MIN(N4:N64) -> 19043124

Sheet 结果
B2: 结果：概率意义上的“够”
B3: 以下蒙特卡洛数值来自 4,000 条路径、90% 置信度；改参数后请在 HTML 计算器重算。
B5: 目标本金（90%） | C5: 18619052 | D5: 今天币值
B6: 当前资产 | C6: 3000000
B7: 覆盖率 | C7: 0.16112528
B8: 当前资产成功率（不再工作） | C8: 0
B9: 活到 90 岁条件下成功率 | C9: 0
B10: 首年总支出 | C10: 280183.03
B11: 首年总支出 / 目标本金 | C11: 0.01504819
B12: 当前资产可支撑核心生活费 | C12: 0 | D12: 元/年
B13: 4% 法则本金 | C13: 7004575.8
B14: 4% 法则在本模型下的成功率 | C14: 0.15575
B16: 置信度区间
B17: 目标置信度 | C17: 所需本金 | D17: 相当于首年支出 | E17: 说明
B18: 80% | C18: 14819051 | D18: 52.9× | E18: 进取
B19: 90% | C19: 18619052 | D19: 66.5× | E19: 推荐
B20: 95% | C20: 22680641 | D20: 80.9× | E20: 更稳
B21: 99% | C21: 34134928 | D21: 121.8× | E21: 更稳
B23: 首年现金流
B24: 项目 | C24: 金额（元） | E24: 备注
B25: 核心生活 | C25: 151200
B26: 医疗（日常） | C26: 12000
B27: 商业保险 | C27: 12000
B28: 房贷 / 居住 | C28: 84983.016
B29: 子女 | C29: 20000
B30: 父母赡养 | C30: 0
B31: 长期护理 | C31: 0
B32: 大件 | C32: 0
B33: 压力测试（目标本金下） | C33: 280183.03 | E33: 首年
B34: 情景 | C34: 成功率 | E34: 说明
B35: 基准 | C35: 0.893
B36: 退休后前3年连续大跌 | C36: 0.2855
B37: 滞胀10年（通胀5%） | C37: 0.3585
B38: 日本化20年（收益1%） | C38: 0.8605
B39: 养老金下调30% | C39: 0.8905
B40: 活到105岁 | C40: 0.7515
B43: 结论
B44: 按当前参数，90% 置信度目标约 1,862 万元；当前资产 300 万元，覆盖率 16%。4% 法则给出 700 万元，但在本模型下只有 16% 成功率。

Sheet 敏感性
B2: 敏感性：参数变化时，90% 目标本金怎么变
B3: 敏感性内部同一样本（800 路径）；与结果表主目标（4,000 路径）有抽样差异。low = 更乐观（本金更低），high = 更悲观。
B5: 参数 | C5: 基准 | D5: 更乐观 | E5: 更悲观 | F5: 乐观标签 | G5: 悲观标签 | H5: 影响幅度
B6: 日常支出 | C6: 19057040 | D6: 16901362 | E6: 21436222 | F6: -20% | G6: +20% | H6: 0.23796247
B7: 投资净收益 | C7: 19057040 | D7: 13337134 | E7: 29300859 | F7: +1.5% | G7: -1.5% | H7: 0.83768128
B8: 通胀中枢 | C8: 19057040 | D8: 15076085 | E8: 24943079 | F8: -1% | G8: +1% | H8: 0.51776112
B9: 医疗通胀 | C9: 19057040 | D9: 17816485 | E9: 22329995 | F9: -2% | G9: +2% | H9: 0.23684211
B10: 子女成本 | C10: 19057040 | D10: 18872277 | E10: 19268199 | F10: -30% | G10: +30% | H10: 0.020775623
B11: 养老金 | C11: 19057040 | D11: 19004251 | E11: 19162620 | F11: +20% | G11: -30% | H11: 0.0083102493
B12: 护理成本 | C12: 19057040 | D12: 18608329 | E12: 19690515 | F12: -50% | G12: +50% | H12: 0.056786704
B13: 寿命 | C13: 19057040 | D13: 16892667 | E13: 19189014 | F13: -10% | G13: +10% | H13: 0.12049861

Sheet 数据与来源
B2: 关键数据与来源
B3: 截至 2026-10-25；政策类尽量用政府原文，数值类标注年份与口径。
B5: 数据 | C5: 数值 | D5: 年份/口径 | E5: 来源 | F5: 链接
B6: 全国居民人均消费支出 | C6: 29,476 元/年 | D6: 2025 | E6: 国家统计局 | F6: 链接
B7: 城镇居民人均消费支出 | C7: 35,869 元/年 | D7: 2025 | E7: 国家统计局 | F7: 链接
B8: 北京城镇居民人均消费 | C8: 54,122 元/年 | D8: 2025 | E8: 北京市统计局 | F8: 链接
B9: 上海城镇居民人均消费 | C9: 57,076 元/年 | D9: 2025 | E9: 上海市统计局 | F9: 链接
B10: CPI | C10: 2024 +0.2% / 2025 0.0% / 2026-09 +0.9% | D10: 2024–2026 | E10: 国家统计局 | F10: 链接
B11: 人均预期寿命 | C11: 79.25 岁 | D11: 2025 | E11: 国家卫健委 | F11: 链接
B12: 卫生总费用 / 人均 | C12: 93,367.2 亿元 / 6,637.9 元 | D12: 2025 | E12: 国家卫健委卫生发展研究中心 | F12: 链接
B13: 个人卫生支出占比 | C13: 27.1% | D13: 2025 | E13: 同上 | F13: 链接
B14: 企业退休月人均养老金 | C14: 3,162 元 | D14: 2023 | E14: 全国人大常委会社保法执法检查报告 | F14: 链接
B15: 2024 / 2025 养老金调整 | C15: +3% / +2% | D15: 2024 / 2025 | E15: 人社部、财政部 | F15: 链接
B16: 城乡居民基础养老金最低标准 | C16: 163 元/月 | D16: 2026 | E16: 政府工作报告 | F16: 链接
... B25: 4% 法则 | C25: 美国 1926–1992，30 年，50/50 股债 | D25: 1994 | E25: Bengen, JFP 7(4) | F25: 链接
